INFO:__main__:Preparing data...
Traceback (most recent call last):
  File "/home/blvksh33p/Documents/models/missing_data_imputation/src/train.py", line 257, in <module>
    main(args.config)
  File "/home/blvksh33p/Documents/models/missing_data_imputation/src/train.py", line 148, in main
    train_loader, val_loader, preprocessor = prepare_data(data_config)
  File "/home/blvksh33p/Documents/models/missing_data_imputation/src/train.py", line 56, in prepare_data
    preprocessor = DataPreprocessor(
TypeError: DataPreprocessor.__init__() got an unexpected keyword argument 'categorical_encoding'
Traceback (most recent call last):
  File "/home/blvksh33p/Documents/models/missing_data_imputation/src/train.py", line 257, in <module>
    main(args.config)
  File "/home/blvksh33p/Documents/models/missing_data_imputation/src/train.py", line 148, in main
    train_loader, val_loader, preprocessor = prepare_data(data_config)
  File "/home/blvksh33p/Documents/models/missing_data_imputation/src/train.py", line 56, in prepare_data
    preprocessor = DataPreprocessor(
TypeError: DataPreprocessor.__init__() got an unexpected keyword argument 'categorical_encoding'
